Workbook

Sheet onboarding_funnel_dataset
A1: user_id | B1: timestamp | C1: event
A2: 5186 | B2: 45292.054 | C2: registration
A3: 1087 | B3: 45292.111 | C3: registration
A4: 6536 | B4: 45292.147 | C4: registration
A5: 3273 | B5: 45292.152 | C5: registration
A6: 7437 | B6: 45292.158 | C6: registration
A7: 467 | B7: 45292.177 | C7: registration
A8: 4490 | B8: 45292.203 | C8: registration
A9: 1967 | B9: 45292.243 | C9: registration
A10: 3419 | B10: 45292.268 | C10: registration
A11: 7246 | B11: 45292.288 | C11: profile_completed
A12: 2169 | B12: 45292.302 | C12: registration
A13: 6275 | B13: 45292.307 | C13: registration
... A3000: 249 | B3000: 45336.964 | C3000: purchase
A3001: 4568 | C3001: profile_completed
A3002: 6022 | C3002: profile_completed
A3003: 9 | C3003: registration
A3004: 2352 | C3004: purchase
A3005: 6345 | C3005: purchase
A3006: 5127 | C3006: profile_completed
A3007: 738 | C3007: purchase
A3008: 6996 | C3008: registration
A3009: 551 | C3009: profile_completed
A3010: 2459 | C3010: view_product
A3011: 2978 | C3011: registration
A3012: 1818 | C3012: add_to_cart
... A12206: 7616 | C12206: purchase

Sheet purchases
A1: user_id | B1: timestamp | C1: event | D1: date | E1: week_start | F1: month_start
A2: =IFERROR(__xludf.DUMMYFUNCTION("FILTER(onboarding_funnel_dataset!A2:C12206, onboarding_funnel_dataset!C2:C12206 = ""purchase"") "),6536) -> 6536 | B2: =IFERROR(__xludf.DUMMYFUNCTION("""COMPUTED_VALUE"""),45293.2406134259) -> 45293.241 | C2: =IFERROR(__xludf.DUMMYFUNCTION("""COMPUTED_VALUE"""),"purchase") -> purchase | D2: =INT(B2) -> 45293 | E2: =D2-WEEKDAY(D2,2)+1 -> 45292 | F2: =DATE(YEAR(D2), MONTH(D2), 1) -> 45292
A3: =IFERROR(__xludf.DUMMYFUNCTION("""COMPUTED_VALUE"""),510) -> 510 | B3: =IFERROR(__xludf.DUMMYFUNCTION("""COMPUTED_VALUE"""),45294.1383680555) -> 45294.138 | C3: =IFERROR(__xludf.DUMMYFUNCTION("""COMPUTED_VALUE"""),"purchase") -> purchase | D3: =INT(B3) -> 45294 | E3: =D3-WEEKDAY(D3,2)+1 -> 45292 | F3: =DATE(YEAR(D3), MONTH(D3), 1) -> 45292
A4: =IFERROR(__xludf.DUMMYFUNCTION("""COMPUTED_VALUE"""),5872) -> 5872 | B4: =IFERROR(__xludf.DUMMYFUNCTION("""COMPUTED_VALUE"""),45294.1801851851) -> 45294.18 | C4: =IFERROR(__xludf.DUMMYFUNCTION("""COMPUTED_VALUE"""),"purchase") -> purchase | D4: =INT(B4) -> 45294 | E4: =D4-WEEKDAY(D4,2)+1 -> 45292 | F4: =DATE(YEAR(D4), MONTH(D4), 1) -> 45292
A5: =IFERROR(__xludf.DUMMYFUNCTION("""COMPUTED_VALUE"""),6275) -> 6275 | B5: =IFERROR(__xludf.DUMMYFUNCTION("""COMPUTED_VALUE"""),45294.6627083333) -> 45294.663 | C5: =IFERROR(__xludf.DUMMYFUNCTION("""COMPUTED_VALUE"""),"purchase") -> purchase | D5: =INT(B5) -> 45294 | E5: =D5-WEEKDAY(D5,2)+1 -> 45292 | F5: =DATE(YEAR(D5), MONTH(D5), 1) -> 45292
A6: =IFERROR(__xludf.DUMMYFUNCTION("""COMPUTED_VALUE"""),1374) -> 1374 | B6: =IFERROR(__xludf.DUMMYFUNCTION("""COMPUTED_VALUE"""),45295.1192708333) -> 45295.119 | C6: =IFERROR(__xludf.DUMMYFUNCTION("""COMPUTED_VALUE"""),"purchase") -> purchase | D6: =INT(B6) -> 45295 | E6: =D6-WEEKDAY(D6,2)+1 -> 45292 | F6: =DATE(YEAR(D6), MONTH(D6), 1) -> 45292
A7: =IFERROR(__xludf.DUMMYFUNCTION("""COMPUTED_VALUE"""),504) -> 504 | B7: =IFERROR(__xludf.DUMMYFUNCTION("""COMPUTED_VALUE"""),45295.2700462962) -> 45295.27 | C7: =IFERROR(__xludf.DUMMYFUNCTION("""COMPUTED_VALUE"""),"purchase") -> purchase | D7: =INT(B7) -> 45295 | E7: =D7-WEEKDAY(D7,2)+1 -> 45292 | F7: =DATE(YEAR(D7), MONTH(D7), 1) -> 45292
A8: =IFERROR(__xludf.DUMMYFUNCTION("""COMPUTED_VALUE"""),1314) -> 1314 | B8: =IFERROR(__xludf.DUMMYFUNCTION("""COMPUTED_VALUE"""),45295.3218518518) -> 45295.322 | C8: =IFERROR(__xludf.DUMMYFUNCTION("""COMPUTED_VALUE"""),"purchase") -> purchase | D8: =INT(B8) -> 45295 | E8: =D8-WEEKDAY(D8,2)+1 -> 45292 | F8: =DATE(YEAR(D8), MONTH(D8), 1) -> 45292
A9: =IFERROR(__xludf.DUMMYFUNCTION("""COMPUTED_VALUE"""),5888) -> 5888 | B9: =IFERROR(__xludf.DUMMYFUNCTION("""COMPUTED_VALUE"""),45295.3429513887) -> 45295.343 | C9: =IFERROR(__xludf.DUMMYFUNCTION("""COMPUTED_VALUE"""),"purchase") -> purchase | D9: =INT(B9) -> 45295 | E9: =D9-WEEKDAY(D9,2)+1 -> 45292 | F9: =DATE(YEAR(D9), MONTH(D9), 1) -> 45292
A10: =IFERROR(__xludf.DUMMYFUNCTION("""COMPUTED_VALUE"""),1704) -> 1704 | B10: =IFERROR(__xludf.DUMMYFUNCTION("""COMPUTED_VALUE"""),45295.4683449074) -> 45295.468 | C10: =IFERROR(__xludf.DUMMYFUNCTION("""COMPUTED_VALUE"""),"purchase") -> purchase | D10: =INT(B10) -> 45295 | E10: =D10-WEEKDAY(D10,2)+1 -> 45292 | F10: =DATE(YEAR(D10), MONTH(D10), 1) -> 45292
A11: =IFERROR(__xludf.DUMMYFUNCTION("""COMPUTED_VALUE"""),3575) -> 3575 | B11: =IFERROR(__xludf.DUMMYFUNCTION("""COMPUTED_VALUE"""),45295.5886458333) -> 45295.589 | C11: =IFERROR(__xludf.DUMMYFUNCTION("""COMPUTED_VALUE"""),"purchase") -> purchase | D11: =INT(B11) -> 45295 | E11: =D11-WEEKDAY(D11,2)+1 -> 45292 | F11: =DATE(YEAR(D11), MONTH(D11), 1) -> 45292
A12: =IFERROR(__xludf.DUMMYFUNCTION("""COMPUTED_VALUE"""),5565) -> 5565 | B12: =IFERROR(__xludf.DUMMYFUNCTION("""COMPUTED_VALUE"""),45295.8714583333) -> 45295.871 | C12: =IFERROR(__xludf.DUMMYFUNCTION("""COMPUTED_VALUE"""),"purchase") -> purchase | D12: =INT(B12) -> 45295 | E12: =D12-WEEKDAY(D12,2)+1 -> 45292 | F12: =DATE(YEAR(D12), MONTH(D12), 1) -> 45292
A13: =IFERROR(__xludf.DUMMYFUNCTION("""COMPUTED_VALUE"""),211) -> 211 | B13: =IFERROR(__xludf.DUMMYFUNCTION("""COMPUTED_VALUE"""),45295.9390856481) -> 45295.939 | C13: =IFERROR(__xludf.DUMMYFUNCTION("""COMPUTED_VALUE"""),"purchase") -> purchase | D13: =INT(B13) -> 45295 | E13: =D13-WEEKDAY(D13,2)+1 -> 45292 | F13: =DATE(YEAR(D13), MONTH(D13), 1) -> 45292
A14: =IFERROR(__xludf.DUMMYFUNCTION("""COMPUTED_VALUE"""),1738) -> 1738 | B14: =IFERROR(__xludf.DUMMYFUNCTION("""COMPUTED_VALUE"""),45296.0533680555) -> 45296.053 | C14: =IFERROR(__xludf.DUMMYFUNCTION("""COMPUTED_VALUE"""),"purchase") -> purchase | D14: =INT(B14) -> 45296 | E14: =D14-WEEKDAY(D14,2)+1 -> 45292 | F14: =DATE(YEAR(D14), MONTH(D14), 1) -> 45292
A15: =IFERROR(__xludf.DUMMYFUNCTION("""COMPUTED_VALUE"""),6522) -> 6522 | B15: =IFERROR(__xludf.DUMMYFUNCTION("""COMPUTED_VALUE"""),45296.0851388887) -> 45296.085 | C15: =IFERROR(__xludf.DUMMYFUNCTION("""COMPUTED_VALUE"""),"purchase") -> purchase | D15: =INT(B15) -> 45296 | E15: =D15-WEEKDAY(D15,2)+1 -> 45292 | F15: =DATE(YEAR(D15), MONTH(D15), 1) -> 45292
A16: =IFERROR(__xludf.DUMMYFUNCTION("""COMPUTED_VALUE"""),7602) -> 7602 | B16: =IFERROR(__xludf.DUMMYFUNCTION("""COMPUTED_VALUE"""),45296.3326388888) -> 45296.333 | C16: =IFERROR(__xludf.DUMMYFUNCTION("""COMPUTED_VALUE"""),"purchase") -> purchase | D16: =INT(B16) -> 45296 | E16: =D16-WEEKDAY(D16,2)+1 -> 45292 | F16: =DATE(YEAR(D16), MONTH(D16), 1) -> 45292
A17: =IFERROR(__xludf.DUMMYFUNCTION("""COMPUTED_VALUE"""),7811) -> 7811 | B17: =IFERROR(__xludf.DUMMYFUNCTION("""COMPUTED_VALUE"""),45296.3785532407) -> 45296.379 | C17: =IFERROR(__xludf.DUMMYFUNCTION("""COMPUTED_VALUE"""),"purchase") -> purchase | D17: =INT(B17) -> 45296 | E17: =D17-WEEKDAY(D17,2)+1 -> 45292 | F17: =DATE(YEAR(D17), MONTH(D17), 1) -> 45292
A18: =IFERROR(__xludf.DUMMYFUNCTION("""COMPUTED_VALUE"""),4490) -> 4490 | B18: =IFERROR(__xludf.DUMMYFUNCTION("""COMPUTED_VALUE"""),45296.4332754629) -> 45296.433 | C18: =IFERROR(__xludf.DUMMYFUNCTION("""COMPUTED_VALUE"""),"purchase") -> purchase | D18: =INT(B18) -> 45296 | E18: =D18-WEEKDAY(D18,2)+1 -> 45292 | F18: =DATE(YEAR(D18), MONTH(D18), 1) -> 45292
A19: =IFERROR(__xludf.DUMMYFUNCTION("""COMPUTED_VALUE"""),3255) -> 3255 | B19: =IFERROR(__xludf.DUMMYFUNCTION("""COMPUTED_VALUE"""),45296.7306481481) -> 45296.731 | C19: =IFERROR(__xludf.DUMMYFUNCTION("""COMPUTED_VALUE"""),"purchase") -> purchase | D19: =INT(B19) -> 45296 | E19: =D19-WEEKDAY(D19,2)+1 -> 45292 | F19: =DATE(YEAR(D19), MONTH(D19), 1) -> 45292
A20: =IFERROR(__xludf.DUMMYFUNCTION("""COMPUTED_VALUE"""),5147) -> 5147 | B20: =IFERROR(__xludf.DUMMYFUNCTION("""COMPUTED_VALUE"""),45296.8191435185) -> 45296.819 | C20: =IFERROR(__xludf.DUMMYFUNCTION("""COMPUTED_VALUE"""),"purchase") -> purchase | D20: =INT(B20) -> 45296 | E20: =D20-WEEKDAY(D20,2)+1 -> 45292 | F20: =DATE(YEAR(D20), MONTH(D20), 1) -> 45292
A21: =IFERROR(__xludf.DUMMYFUNCTION("""COMPUTED_VALUE"""),4032) -> 4032 | B21: =IFERROR(__xludf.DUMMYFUNCTION("""COMPUTED_VALUE"""),45296.9624652777) -> 45296.962 | C21: =IFERROR(__xludf.DUMMYFUNCTION("""COMPUTED_VALUE"""),"purchase") -> purchase | D21: =INT(B21) -> 45296 | E21: =D21-WEEKDAY(D21,2)+1 -> 45292 | F21: =DATE(YEAR(D21), MONTH(D21), 1) -> 45292
A22: =IFERROR(__xludf.DUMMYFUNCTION("""COMPUTED_VALUE"""),3218) -> 3218 | B22: =IFERROR(__xludf.DUMMYFUNCTION("""COMPUTED_VALUE"""),45297.2231018518) -> 45297.223 | C22: =IFERROR(__xludf.DUMMYFUNCTION("""COMPUTED_VALUE"""),"purchase") -> purchase | D22: =INT(B22) -> 45297 | E22: =D22-WEEKDAY(D22,2)+1 -> 45292 | F22: =DATE(YEAR(D22), MONTH(D22), 1) -> 45292
A23: =IFERROR(__xludf.DUMMYFUNCTION("""COMPUTED_VALUE"""),4776) -> 4776 | B23: =IFERROR(__xludf.DUMMYFUNCTION("""COMPUTED_VALUE"""),45297.2730208333) -> 45297.273 | C23: =IFERROR(__xludf.DUMMYFUNCTION("""COMPUTED_VALUE"""),"purchase") -> purchase | D23: =INT(B23) -> 45297 | E23: =D23-WEEKDAY(D23,2)+1 -> 45292 | F23: =DATE(YEAR(D23), MONTH(D23), 1) -> 45292
A24: =IFERROR(__xludf.DUMMYFUNCTION("""COMPUTED_VALUE"""),5781) -> 5781 | B24: =IFERROR(__xludf.DUMMYFUNCTION("""COMPUTED_VALUE"""),45297.3751736111) -> 45297.375 | C24: =IFERROR(__xludf.DUMMYFUNCTION("""COMPUTED_VALUE"""),"purchase") -> purchase | D24: =INT(B24) -> 45297 | E24: =D24-WEEKDAY(D24,2)+1 -> 45292 | F24: =DATE(YEAR(D24), MONTH(D24), 1) -> 45292
A25: =IFERROR(__xludf.DUMMYFUNCTION("""COMPUTED_VALUE"""),7489) -> 7489 | B25: =IFERROR(__xludf.DUMMYFUNCTION("""COMPUTED_VALUE"""),45297.5116782407) -> 45297.512 | C25: =IFERROR(__xludf.DUMMYFUNCTION("""COMPUTED_VALUE"""),"purchase") -> purchase | D25: =INT(B25) -> 45297 | E25: =D25-WEEKDAY(D25,2)+1 -> 45292 | F25: =DATE(YEAR(D25), MONTH(D25), 1) -> 45292
A26: =IFERROR(__xludf.DUMMYFUNCTION("""COMPUTED_VALUE"""),6460) -> 6460 | B26: =IFERROR(__xludf.DUMMYFUNCTION("""COMPUTED_VALUE"""),45297.6974884259) -> 45297.697 | C26: =IFERROR(__xludf.DUMMYFUNCTION("""COMPUTED_VALUE"""),"purchase") -> purchase | D26: =INT(B26) -> 45297 | E26: =D26-WEEKDAY(D26,2)+1 -> 45292 | F26: =DATE(YEAR(D26), MONTH(D26), 1) -> 45292
A27: =IFERROR(__xludf.DUMMYFUNCTION("""COMPUTED_VALUE"""),6612) -> 6612 | B27: =IFERROR(__xludf.DUMMYFUNCTION("""COMPUTED_VALUE"""),45297.7163657407) -> 45297.716 | C27: =IFERROR(__xludf.DUMMYFUNCTION("""COMPUTED_VALUE"""),"purchase") -> purchase | D27: =INT(B27) -> 45297 | E27: =D27-WEEKDAY(D27,2)+1 -> 45292 | F27: =DATE(YEAR(D27), MONTH(D27), 1) -> 45292
A28: =IFERROR(__xludf.DUMMYFUNCTION("""COMPUTED_VALUE"""),7822) -> 7822 | B28: =IFERROR(__xludf.DUMMYFUNCTION("""COMPUTED_VALUE"""),45298.2720601851) -> 45298.272 | C28: =IFERROR(__xludf.DUMMYFUNCTION("""COMPUTED_VALUE"""),"purchase") -> purchase | D28: =INT(B28) -> 45298 | E28: =D28-WEEKDAY(D28,2)+1 -> 45292 | F28: =DATE(YEAR(D28), MONTH(D28), 1) -> 45292
A29: =IFERROR(__xludf.DUMMYFUNCTION("""COMPUTED_VALUE"""),3533) -> 3533 | B29: =IFERROR(__xludf.DUMMYFUNCTION("""COMPUTED_VALUE"""),45298.3189467592) -> 45298.319 | C29: =IFERROR(__xludf.DUMMYFUNCTION("""COMPUTED_VALUE"""),"purchase") -> purchase | D29: =INT(B29) -> 45298 | E29: =D29-WEEKDAY(D29,2)+1 -> 45292 | F29: =DATE(YEAR(D29), MONTH(D29), 1) -> 45292
A30: =IFERROR(__xludf.DUMMYFUNCTION("""COMPUTED_VALUE"""),3419) -> 3419 | B30: =IFERROR(__xludf.DUMMYFUNCTION("""COMPUTED_VALUE"""),45298.7319212963) -> 45298.732 | C30: =IFERROR(__xludf.DUMMYFUNCTION("""COMPUTED_VALUE"""),"purchase") -> purchase | D30: =INT(B30) -> 45298 | E30: =D30-WEEKDAY(D30,2)+1 -> 45292 | F30: =DATE(YEAR(D30), MONTH(D30), 1) -> 45292
A31: =IFERROR(__xludf.DUMMYFUNCTION("""COMPUTED_VALUE"""),5194) -> 5194 | B31: =IFERROR(__xludf.DUMMYFUNCTION("""COMPUTED_VALUE"""),45298.848449074) -> 45298.848 | C31: =IFERROR(__xludf.DUMMYFUNCTION("""COMPUTED_VALUE"""),"purchase") -> purchase | D31: =INT(B31) -> 45298 | E31: =D31-WEEKDAY(D31,2)+1 -> 45292 | F31: =DATE(YEAR(D31), MONTH(D31), 1) -> 45292
A32: =IFERROR(__xludf.DUMMYFUNCTION("""COMPUTED_VALUE"""),7003) -> 7003 | B32: =IFERROR(__xludf.DUMMYFUNCTION("""COMPUTED_VALUE"""),45298.9529166666) -> 45298.953 | C32: =IFERROR(__xludf.DUMMYFUNCTION("""COMPUTED_VALUE"""),"purchase") -> purchase | D32: =INT(B32) -> 45298 | E32: =D32-WEEKDAY(D32,2)+1 -> 45292 | F32: =DATE(YEAR(D32), MONTH(D32), 1) -> 45292
A33: =IFERROR(__xludf.DUMMYFUNCTION("""COMPUTED_VALUE"""),2405) -> 2405 | B33: =IFERROR(__xludf.DUMMYFUNCTION("""COMPUTED_VALUE"""),45299.1285300925) -> 45299.129 | C33: =IFERROR(__xludf.DUMMYFUNCTION("""COMPUTED_VALUE"""),"purchase") -> purchase | D33: =INT(B33) -> 45299 | E33: =D33-WEEKDAY(D33,2)+1 -> 45299 | F33: =DATE(YEAR(D33), MONTH(D33), 1) -> 45292
A34: =IFERROR(__xludf.DUMMYFUNCTION("""COMPUTED_VALUE"""),765) -> 765 | B34: =IFERROR(__xludf.DUMMYFUNCTION("""COMPUTED_VALUE"""),45299.1498032407) -> 45299.15 | C34: =IFERROR(__xludf.DUMMYFUNCTION("""COMPUTED_VALUE"""),"purchase") -> purchase | D34: =INT(B34) -> 45299 | E34: =D34-WEEKDAY(D34,2)+1 -> 45299 | F34: =DATE(YEAR(D34), MONTH(D34), 1) -> 45292
A35: =IFERROR(__xludf.DUMMYFUNCTION("""COMPUTED_VALUE"""),2993) -> 2993 | B35: =IFERROR(__xludf.DUMMYFUNCTION("""COMPUTED_VALUE"""),45299.2696064814) -> 45299.27 | C35: =IFERROR(__xludf.DUMMYFUNCTION("""COMPUTED_VALUE"""),"purchase") -> purchase | D35: =INT(B35) -> 45299 | E35: =D35-WEEKDAY(D35,2)+1 -> 45299 | F35: =DATE(YEAR(D35), MONTH(D35), 1) -> 45292
A36: =IFERROR(__xludf.DUMMYFUNCTION("""COMPUTED_VALUE"""),4363) -> 4363 | B36: =IFERROR(__xludf.DUMMYFUNCTION("""COMPUTED_VALUE"""),45299.2846527777) -> 45299.285 | C36: =IFERROR(__xludf.DUMMYFUNCTION("""COMPUTED_VALUE"""),"purchase") -> purchase | D36: =INT(B36) -> 45299 | E36: =D36-WEEKDAY(D36,2)+1 -> 45299 | F36: =DATE(YEAR(D36), MONTH(D36), 1) -> 45292
A37: =IFERROR(__xludf.DUMMYFUNCTION("""COMPUTED_VALUE"""),7467) -> 7467 | B37: =IFERROR(__xludf.DUMMYFUNCTION("""COMPUTED_VALUE"""),45299.6007175925) -> 45299.601 | C37: =IFERROR(__xludf.DUMMYFUNCTION("""COMPUTED_VALUE"""),"purchase") -> purchase | D37: =INT(B37) -> 45299 | E37: =D37-WEEKDAY(D37,2)+1 -> 45299 | F37: =DATE(YEAR(D37), MONTH(D37), 1) -> 45292
A38: =IFERROR(__xludf.DUMMYFUNCTION("""COMPUTED_VALUE"""),4592) -> 4592 | B38: =IFERROR(__xludf.DUMMYFUNCTION("""COMPUTED_VALUE"""),45299.701412037) -> 45299.701 | C38: =IFERROR(__xludf.DUMMYFUNCTION("""COMPUTED_VALUE"""),"purchase") -> purchase | D38: =INT(B38) -> 45299 | E38: =D38-WEEKDAY(D38,2)+1 -> 45299 | F38: =DATE(YEAR(D38), MONTH(D38), 1) -> 45292
A39: =IFERROR(__xludf.DUMMYFUNCTION("""COMPUTED_VALUE"""),4321) -> 4321 | B39: =IFERROR(__xludf.DUMMYFUNCTION("""COMPUTED_VALUE"""),45299.7915509259) -> 45299.792 | C39: =IFERROR(__xludf.DUMMYFUNCTION("""COMPUTED_VALUE"""),"purchase") -> purchase | D39: =INT(B39) -> 45299 | E39: =D39-WEEKDAY(D39,2)+1 -> 45299 | F39: =DATE(YEAR(D39), MONTH(D39), 1) -> 45292
A40: =IFERROR(__xludf.DUMMYFUNCTION("""COMPUTED_VALUE"""),5186) -> 5186 | B40: =IFERROR(__xludf.DUMMYFUNCTION("""COMPUTED_VALUE"""),45299.8332407406) -> 45299.833 | C40: =IFERROR(__xludf.DUMMYFUNCTION("""COMPUTED_VALUE"""),"purchase") -> purchase | D40: =INT(B40) -> 45299 | E40: =D40-WEEKDAY(D40,2)+1 -> 45299 | F40: =DATE(YEAR(D40), MONTH(D40), 1) -> 45292
...

Sheet dau
A1: Date | B1: DAU | C1: Month_start
A2: 45293 | B2: =IFERROR(__xludf.DUMMYFUNCTION("COUNTUNIQUEIFS(purchases!$A$2:$A$2001,purchases!D2:D2001,A2)"),1) -> 1 | C2: =VLOOKUP(A2,purchases!$D$2:$F$2001,3,FALSE) -> 45292
A3: 45294 | B3: =IFERROR(__xludf.DUMMYFUNCTION("COUNTUNIQUEIFS(purchases!$A$2:$A$2001,purchases!D3:D2002,A3)"),3) -> 3 | C3: =VLOOKUP(A3,purchases!$D$2:$F$2001,3,FALSE) -> 45292
A4: 45295 | B4: =IFERROR(__xludf.DUMMYFUNCTION("COUNTUNIQUEIFS(purchases!$A$2:$A$2001,purchases!D4:D2003,A4)"),8) -> 8 | C4: =VLOOKUP(A4,purchases!$D$2:$F$2001,3,FALSE) -> 45292
A5: 45296 | B5: =IFERROR(__xludf.DUMMYFUNCTION("COUNTUNIQUEIFS(purchases!$A$2:$A$2001,purchases!D5:D2004,A5)"),8) -> 8 | C5: =VLOOKUP(A5,purchases!$D$2:$F$2001,3,FALSE) -> 45292
A6: 45297 | B6: =IFERROR(__xludf.DUMMYFUNCTION("COUNTUNIQUEIFS(purchases!$A$2:$A$2001,purchases!D6:D2005,A6)"),6) -> 6 | C6: =VLOOKUP(A6,purchases!$D$2:$F$2001,3,FALSE) -> 45292
A7: 45298 | B7: =IFERROR(__xludf.DUMMYFUNCTION("COUNTUNIQUEIFS(purchases!$A$2:$A$2001,purchases!D7:D2006,A7)"),5) -> 5 | C7: =VLOOKUP(A7,purchases!$D$2:$F$2001,3,FALSE) -> 45292
A8: 45299 | B8: =IFERROR(__xludf.DUMMYFUNCTION("COUNTUNIQUEIFS(purchases!$A$2:$A$2001,purchases!D8:D2007,A8)"),8) -> 8 | C8: =VLOOKUP(A8,purchases!$D$2:$F$2001,3,FALSE) -> 45292
A9: 45300 | B9: =IFERROR(__xludf.DUMMYFUNCTION("COUNTUNIQUEIFS(purchases!$A$2:$A$2001,purchases!D9:D2008,A9)"),5) -> 5 | C9: =VLOOKUP(A9,purchases!$D$2:$F$2001,3,FALSE) -> 45292
A10: 45301 | B10: =IFERROR(__xludf.DUMMYFUNCTION("COUNTUNIQUEIFS(purchases!$A$2:$A$2001,purchases!D10:D2009,A10)"),16) -> 16 | C10: =VLOOKUP(A10,purchases!$D$2:$F$2001,3,FALSE) -> 45292
A11: 45302 | B11: =IFERROR(__xludf.DUMMYFUNCTION("COUNTUNIQUEIFS(purchases!$A$2:$A$2001,purchases!D11:D2010,A11)"),13) -> 13 | C11: =VLOOKUP(A11,purchases!$D$2:$F$2001,3,FALSE) -> 45292
A12: 45303 | B12: =IFERROR(__xludf.DUMMYFUNCTION("COUNTUNIQUEIFS(purchases!$A$2:$A$2001,purchases!D12:D2011,A12)"),11) -> 11 | C12: =VLOOKUP(A12,purchases!$D$2:$F$2001,3,FALSE) -> 45292
A13: 45304 | B13: =IFERROR(__xludf.DUMMYFUNCTION("COUNTUNIQUEIFS(purchases!$A$2:$A$2001,purchases!D13:D2012,A13)"),13) -> 13 | C13: =VLOOKUP(A13,purchases!$D$2:$F$2001,3,FALSE) -> 45292
A14: 45305 | B14: =IFERROR(__xludf.DUMMYFUNCTION("COUNTUNIQUEIFS(purchases!$A$2:$A$2001,purchases!D14:D2013,A14)"),9) -> 9 | C14: =VLOOKUP(A14,purchases!$D$2:$F$2001,3,FALSE) -> 45292
A15: 45306 | B15: =IFERROR(__xludf.DUMMYFUNCTION("COUNTUNIQUEIFS(purchases!$A$2:$A$2001,purchases!D15:D2014,A15)"),12) -> 12 | C15: =VLOOKUP(A15,purchases!$D$2:$F$2001,3,FALSE) -> 45292
A16: 45307 | B16: =IFERROR(__xludf.DUMMYFUNCTION("COUNTUNIQUEIFS(purchases!$A$2:$A$2001,purchases!D16:D2015,A16)"),16) -> 16 | C16: =VLOOKUP(A16,purchases!$D$2:$F$2001,3,FALSE) -> 45292
A17: 45308 | B17: =IFERROR(__xludf.DUMMYFUNCTION("COUNTUNIQUEIFS(purchases!$A$2:$A$2001,purchases!D17:D2016,A17)"),15) -> 15 | C17: =VLOOKUP(A17,purchases!$D$2:$F$2001,3,FALSE) -> 45292
A18: 45309 | B18: =IFERROR(__xludf.DUMMYFUNCTION("COUNTUNIQUEIFS(purchases!$A$2:$A$2001,purchases!D18:D2017,A18)"),10) -> 10 | C18: =VLOOKUP(A18,purchases!$D$2:$F$2001,3,FALSE) -> 45292
A19: 45310 | B19: =IFERROR(__xludf.DUMMYFUNCTION("COUNTUNIQUEIFS(purchases!$A$2:$A$2001,purchases!D19:D2018,A19)"),12) -> 12 | C19: =VLOOKUP(A19,purchases!$D$2:$F$2001,3,FALSE) -> 45292
A20: 45311 | B20: =IFERROR(__xludf.DUMMYFUNCTION("COUNTUNIQUEIFS(purchases!$A$2:$A$2001,purchases!D20:D2019,A20)"),13) -> 13 | C20: =VLOOKUP(A20,purchases!$D$2:$F$2001,3,FALSE) -> 45292
A21: 45312 | B21: =IFERROR(__xludf.DUMMYFUNCTION("COUNTUNIQUEIFS(purchases!$A$2:$A$2001,purchases!D21:D2020,A21)"),6) -> 6 | C21: =VLOOKUP(A21,purchases!$D$2:$F$2001,3,FALSE) -> 45292
A22: 45313 | B22: =IFERROR(__xludf.DUMMYFUNCTION("COUNTUNIQUEIFS(purchases!$A$2:$A$2001,purchases!D22:D2021,A22)"),13) -> 13 | C22: =VLOOKUP(A22,purchases!$D$2:$F$2001,3,FALSE) -> 45292
A23: 45314 | B23: =IFERROR(__xludf.DUMMYFUNCTION("COUNTUNIQUEIFS(purchases!$A$2:$A$2001,purchases!D23:D2022,A23)"),8) -> 8 | C23: =VLOOKUP(A23,purchases!$D$2:$F$2001,3,FALSE) -> 45292
A24: 45315 | B24: =IFERROR(__xludf.DUMMYFUNCTION("COUNTUNIQUEIFS(purchases!$A$2:$A$2001,purchases!D24:D2023,A24)"),12) -> 12 | C24: =VLOOKUP(A24,purchases!$D$2:$F$2001,3,FALSE) -> 45292
A25: 45316 | B25: =IFERROR(__xludf.DUMMYFUNCTION("COUNTUNIQUEIFS(purchases!$A$2:$A$2001,purchases!D25:D2024,A25)"),12) -> 12 | C25: =VLOOKUP(A25,purchases!$D$2:$F$2001,3,FALSE) -> 45292
A26: 45317 | B26: =IFERROR(__xludf.DUMMYFUNCTION("COUNTUNIQUEIFS(purchases!$A$2:$A$2001,purchases!D26:D2025,A26)"),14) -> 14 | C26: =VLOOKUP(A26,purchases!$D$2:$F$2001,3,FALSE) -> 45292
A27: 45318 | B27: =IFERROR(__xludf.DUMMYFUNCTION("COUNTUNIQUEIFS(purchases!$A$2:$A$2001,purchases!D27:D2026,A27)"),10) -> 10 | C27: =VLOOKUP(A27,purchases!$D$2:$F$2001,3,FALSE) -> 45292
A28: 45319 | B28: =IFERROR(__xludf.DUMMYFUNCTION("COUNTUNIQUEIFS(purchases!$A$2:$A$2001,purchases!D28:D2027,A28)"),4) -> 4 | C28: =VLOOKUP(A28,purchases!$D$2:$F$2001,3,FALSE) -> 45292
A29: 45320 | B29: =IFERROR(__xludf.DUMMYFUNCTION("COUNTUNIQUEIFS(purchases!$A$2:$A$2001,purchases!D29:D2028,A29)"),21) -> 21 | C29: =VLOOKUP(A29,purchases!$D$2:$F$2001,3,FALSE) -> 45292
A30: 45321 | B30: =IFERROR(__xludf.DUMMYFUNCTION("COUNTUNIQUEIFS(purchases!$A$2:$A$2001,purchases!D30:D2029,A30)"),7) -> 7 | C30: =VLOOKUP(A30,purchases!$D$2:$F$2001,3,FALSE) -> 45292
A31: 45322 | B31: =IFERROR(__xludf.DUMMYFUNCTION("COUNTUNIQUEIFS(purchases!$A$2:$A$2001,purchases!D31:D2030,A31)"),4) -> 4 | C31: =VLOOKUP(A31,purchases!$D$2:$F$2001,3,FALSE) -> 45292
A32: 45323 | B32: =IFERROR(__xludf.DUMMYFUNCTION("COUNTUNIQUEIFS(purchases!$A$2:$A$2001,purchases!D32:D2031,A32)"),11) -> 11 | C32: =VLOOKUP(A32,purchases!$D$2:$F$2001,3,FALSE) -> 45323
A33: 45324 | B33: =IFERROR(__xludf.DUMMYFUNCTION("COUNTUNIQUEIFS(purchases!$A$2:$A$2001,purchases!D33:D2032,A33)"),11) -> 11 | C33: =VLOOKUP(A33,purchases!$D$2:$F$2001,3,FALSE) -> 45323
A34: 45325 | B34: =IFERROR(__xludf.DUMMYFUNCTION("COUNTUNIQUEIFS(purchases!$A$2:$A$2001,purchases!D34:D2033,A34)"),12) -> 12 | C34: =VLOOKUP(A34,purchases!$D$2:$F$2001,3,FALSE) -> 45323
A35: 45326 | B35: =IFERROR(__xludf.DUMMYFUNCTION("COUNTUNIQUEIFS(purchases!$A$2:$A$2001,purchases!D35:D2034,A35)"),13) -> 13 | C35: =VLOOKUP(A35,purchases!$D$2:$F$2001,3,FALSE) -> 45323
A36: 45327 | B36: =IFERROR(__xludf.DUMMYFUNCTION("COUNTUNIQUEIFS(purchases!$A$2:$A$2001,purchases!D36:D2035,A36)"),14) -> 14 | C36: =VLOOKUP(A36,purchases!$D$2:$F$2001,3,FALSE) -> 45323
A37: 45328 | B37: =IFERROR(__xludf.DUMMYFUNCTION("COUNTUNIQUEIFS(purchases!$A$2:$A$2001,purchases!D37:D2036,A37)"),10) -> 10 | C37: =VLOOKUP(A37,purchases!$D$2:$F$2001,3,FALSE) -> 45323
A38: 45329 | B38: =IFERROR(__xludf.DUMMYFUNCTION("COUNTUNIQUEIFS(purchases!$A$2:$A$2001,purchases!D38:D2037,A38)"),19) -> 19 | C38: =VLOOKUP(A38,purchases!$D$2:$F$2001,3,FALSE) -> 45323
A39: 45330 | B39: =IFERROR(__xludf.DUMMYFUNCTION("COUNTUNIQUEIFS(purchases!$A$2:$A$2001,purchases!D39:D2038,A39)"),7) -> 7 | C39: =VLOOKUP(A39,purchases!$D$2:$F$2001,3,FALSE) -> 45323
A40: 45331 | B40: =IFERROR(__xludf.DUMMYFUNCTION("COUNTUNIQUEIFS(purchases!$A$2:$A$2001,purchases!D40:D2039,A40)"),9) -> 9 | C40: =VLOOKUP(A40,purchases!$D$2:$F$2001,3,FALSE) -> 45323
...

Sheet wau
A1: Week | B1: WAU | C1: Month_start
A2: 45292 | B2: =IFERROR(__xludf.DUMMYFUNCTION("COUNTUNIQUEIFS(purchases!$A$2:$A$2001,purchases!$E$2:$E$2001,A2)"),31) -> 31 | C2: 45292
A3: 45299 | B3: =IFERROR(__xludf.DUMMYFUNCTION("COUNTUNIQUEIFS(purchases!$A$2:$A$2001,purchases!$E$2:$E$2001,A3)"),75) -> 75 | C3: 45292
A4: 45306 | B4: =IFERROR(__xludf.DUMMYFUNCTION("COUNTUNIQUEIFS(purchases!$A$2:$A$2001,purchases!$E$2:$E$2001,A4)"),84) -> 84 | C4: 45292
A5: 45313 | B5: =IFERROR(__xludf.DUMMYFUNCTION("COUNTUNIQUEIFS(purchases!$A$2:$A$2001,purchases!$E$2:$E$2001,A5)"),73) -> 73 | C5: 45292
A6: 45320 | B6: =IFERROR(__xludf.DUMMYFUNCTION("COUNTUNIQUEIFS(purchases!$A$2:$A$2001,purchases!$E$2:$E$2001,A6)"),79) -> 79 | C6: 45292
A7: 45327 | B7: =IFERROR(__xludf.DUMMYFUNCTION("COUNTUNIQUEIFS(purchases!$A$2:$A$2001,purchases!$E$2:$E$2001,A7)"),82) -> 82 | C7: 45323
A8: 45334 | B8: =IFERROR(__xludf.DUMMYFUNCTION("COUNTUNIQUEIFS(purchases!$A$2:$A$2001,purchases!$E$2:$E$2001,A8)"),72) -> 72 | C8: 45323
A9: 45341 | B9: =IFERROR(__xludf.DUMMYFUNCTION("COUNTUNIQUEIFS(purchases!$A$2:$A$2001,purchases!$E$2:$E$2001,A9)"),72) -> 72 | C9: 45323
A10: 45348 | B10: =IFERROR(__xludf.DUMMYFUNCTION("COUNTUNIQUEIFS(purchases!$A$2:$A$2001,purchases!$E$2:$E$2001,A10)"),77) -> 77 | C10: 45323
A11: 45355 | B11: =IFERROR(__xludf.DUMMYFUNCTION("COUNTUNIQUEIFS(purchases!$A$2:$A$2001,purchases!$E$2:$E$2001,A11)"),80) -> 80 | C11: 45352
A12: 45362 | B12: =IFERROR(__xludf.DUMMYFUNCTION("COUNTUNIQUEIFS(purchases!$A$2:$A$2001,purchases!$E$2:$E$2001,A12)"),82) -> 82 | C12: 45352
A13: 45369 | B13: =IFERROR(__xludf.DUMMYFUNCTION("COUNTUNIQUEIFS(purchases!$A$2:$A$2001,purchases!$E$2:$E$2001,A13)"),94) -> 94 | C13: 45352
A14: 45376 | B14: =IFERROR(__xludf.DUMMYFUNCTION("COUNTUNIQUEIFS(purchases!$A$2:$A$2001,purchases!$E$2:$E$2001,A14)"),90) -> 90 | C14: 45352
A15: 45383 | B15: =IFERROR(__xludf.DUMMYFUNCTION("COUNTUNIQUEIFS(purchases!$A$2:$A$2001,purchases!$E$2:$E$2001,A15)"),71) -> 71 | C15: 45383
A16: 45390 | B16: =IFERROR(__xludf.DUMMYFUNCTION("COUNTUNIQUEIFS(purchases!$A$2:$A$2001,purchases!$E$2:$E$2001,A16)"),72) -> 72 | C16: 45383
A17: 45397 | B17: =IFERROR(__xludf.DUMMYFUNCTION("COUNTUNIQUEIFS(purchases!$A$2:$A$2001,purchases!$E$2:$E$2001,A17)"),81) -> 81 | C17: 45383
A18: 45404 | B18: =IFERROR(__xludf.DUMMYFUNCTION("COUNTUNIQUEIFS(purchases!$A$2:$A$2001,purchases!$E$2:$E$2001,A18)"),74) -> 74 | C18: 45383
A19: 45411 | B19: =IFERROR(__xludf.DUMMYFUNCTION("COUNTUNIQUEIFS(purchases!$A$2:$A$2001,purchases!$E$2:$E$2001,A19)"),68) -> 68 | C19: 45383
A20: 45418 | B20: =IFERROR(__xludf.DUMMYFUNCTION("COUNTUNIQUEIFS(purchases!$A$2:$A$2001,purchases!$E$2:$E$2001,A20)"),69) -> 69 | C20: 45413
A21: 45425 | B21: =IFERROR(__xludf.DUMMYFUNCTION("COUNTUNIQUEIFS(purchases!$A$2:$A$2001,purchases!$E$2:$E$2001,A21)"),74) -> 74 | C21: 45413
A22: 45432 | B22: =IFERROR(__xludf.DUMMYFUNCTION("COUNTUNIQUEIFS(purchases!$A$2:$A$2001,purchases!$E$2:$E$2001,A22)"),76) -> 76 | C22: 45413
A23: 45439 | B23: =IFERROR(__xludf.DUMMYFUNCTION("COUNTUNIQUEIFS(purchases!$A$2:$A$2001,purchases!$E$2:$E$2001,A23)"),70) -> 70 | C23: 45413
A24: 45446 | B24: =IFERROR(__xludf.DUMMYFUNCTION("COUNTUNIQUEIFS(purchases!$A$2:$A$2001,purchases!$E$2:$E$2001,A24)"),71) -> 71 | C24: 45444
A25: 45453 | B25: =IFERROR(__xludf.DUMMYFUNCTION("COUNTUNIQUEIFS(purchases!$A$2:$A$2001,purchases!$E$2:$E$2001,A25)"),79) -> 79 | C25: 45444
A26: 45460 | B26: =IFERROR(__xludf.DUMMYFUNCTION("COUNTUNIQUEIFS(purchases!$A$2:$A$2001,purchases!$E$2:$E$2001,A26)"),63) -> 63 | C26: 45444
A27: 45467 | B27: =IFERROR(__xludf.DUMMYFUNCTION("COUNTUNIQUEIFS(purchases!$A$2:$A$2001,purchases!$E$2:$E$2001,A27)"),71) -> 71 | C27: 45444
A28: 45474 | B28: =IFERROR(__xludf.DUMMYFUNCTION("COUNTUNIQUEIFS(purchases!$A$2:$A$2001,purchases!$E$2:$E$2001,A28)"),67) -> 67 | C28: 45474
A29: 45481 | B29: =IFERROR(__xludf.DUMMYFUNCTION("COUNTUNIQUEIFS(purchases!$A$2:$A$2001,purchases!$E$2:$E$2001,A29)"),3) -> 3 | C29: 45474

Sheet mau
A1: Month | B1: MAU | C1: Average DAU | D1: Average WAU | E1: DAU/MAU | F1: WAU/MAU
A2: 45292 | B2: =IFERROR(__xludf.DUMMYFUNCTION("COUNTUNIQUEIFS(purchases!$A$2:$A$2001,purchases!$F$2:$F$2001,A2)"),295) -> 295 | C2: =AVERAGEIFS(dau!$B$2:$B$190,dau!$C$2:$C$190,A2) -> 9.8333333 | D2: =AVERAGEIFS(wau!$B$2:$B$29,wau!$C$2:$C$29,A2) -> 68.4 | E2: =C2/B2 -> 0.033333333 | F2: =D2/B2 -> 0.23186441
A3: 45323 | B3: =IFERROR(__xludf.DUMMYFUNCTION("COUNTUNIQUEIFS(purchases!$A$2:$A$2001,purchases!$F$2:$F$2001,A3)"),319) -> 319 | C3: =AVERAGEIFS(dau!$B$2:$B$190,dau!$C$2:$C$190,A3) -> 11 | D3: =AVERAGEIFS(wau!$B$2:$B$29,wau!$C$2:$C$29,A3) -> 75.75 | E3: =C3/B3 -> 0.034482759 | F3: =D3/B3 -> 0.23746082
A4: 45352 | B4: =IFERROR(__xludf.DUMMYFUNCTION("COUNTUNIQUEIFS(purchases!$A$2:$A$2001,purchases!$F$2:$F$2001,A4)"),377) -> 377 | C4: =AVERAGEIFS(dau!$B$2:$B$190,dau!$C$2:$C$190,A4) -> 12.16129 | D4: =AVERAGEIFS(wau!$B$2:$B$29,wau!$C$2:$C$29,A4) -> 86.5 | E4: =C4/B4 -> 0.032258065 | F4: =D4/B4 -> 0.22944297
A5: 45383 | B5: =IFERROR(__xludf.DUMMYFUNCTION("COUNTUNIQUEIFS(purchases!$A$2:$A$2001,purchases!$F$2:$F$2001,A5)"),318) -> 318 | C5: =AVERAGEIFS(dau!$B$2:$B$190,dau!$C$2:$C$190,A5) -> 10.6 | D5: =AVERAGEIFS(wau!$B$2:$B$29,wau!$C$2:$C$29,A5) -> 73.2 | E5: =C5/B5 -> 0.033333333 | F5: =D5/B5 -> 0.23018868
A6: 45413 | B6: =IFERROR(__xludf.DUMMYFUNCTION("COUNTUNIQUEIFS(purchases!$A$2:$A$2001,purchases!$F$2:$F$2001,A6)"),316) -> 316 | C6: =AVERAGEIFS(dau!$B$2:$B$190,dau!$C$2:$C$190,A6) -> 10.193548 | D6: =AVERAGEIFS(wau!$B$2:$B$29,wau!$C$2:$C$29,A6) -> 72.25 | E6: =C6/B6 -> 0.032258065 | F6: =D6/B6 -> 0.22863924
A7: 45444 | B7: =IFERROR(__xludf.DUMMYFUNCTION("COUNTUNIQUEIFS(purchases!$A$2:$A$2001,purchases!$F$2:$F$2001,A7)"),305) -> 305 | C7: =AVERAGEIFS(dau!$B$2:$B$190,dau!$C$2:$C$190,A7) -> 10.166667 | D7: =AVERAGEIFS(wau!$B$2:$B$29,wau!$C$2:$C$29,A7) -> 71 | E7: =C7/B7 -> 0.033333333 | F7: =D7/B7 -> 0.23278689
A8: 45474 | B8: =IFERROR(__xludf.DUMMYFUNCTION("COUNTUNIQUEIFS(purchases!$A$2:$A$2001,purchases!$F$2:$F$2001,A8)"),70) -> 70 | C8: =AVERAGEIFS(dau!$B$2:$B$190,dau!$C$2:$C$190,A8) -> 8.75 | D8: =AVERAGEIFS(wau!$B$2:$B$29,wau!$C$2:$C$29,A8) -> 35 | E8: =C8/B8 -> 0.125 | F8: =D8/B8 -> 0.5
C9: Встанови числовий формат 0.00

Sheet questions
A1: Питання | B1: Відповідь
A2: У якому місяці MAU було найвищим? | B2: березень
A3: У якому місяці MAU було найнижчим? | B3: липень
A4: Який тренд має DAU ? | B4: стабільний
A5: Який тренд демонструє WAU ? | B5: негативний
A6: У якому місяці DAU/MAU було найвищим? | B6: липень
A7: Що призвело до стрімкого зростання DAU/MAU ? | B7: падіння MAU
A8: Якщо DAU/MAU ~0.03 — це означає, що продукт… | B8: не викликає щоденої звички
A9: Якщо MAU росте, а DAU/MAU падає — це означає… | B9: нові користувачі малоактивні
A10: Якщо WAU/MAU стабільне, це означає, що користувачі… | B10: стабільно користуються продуктом
